Workbook
Name client_name: [1]Index!$C$5
Name Current_Year: [1]LEAD!$D$6
Name Date.prepared: [1]Index!$J$5
Name Date.reviewed1: [1]Index!$J$6
Name Date.reviewed2: [1]Index!$J$7
Name Last_Year: [1]LEAD!$H$6
Name Period: [1]Index!$C$6
Name Prepared.by: [1]Index!$H$5
Name Reviewed.by1: [1]Index!$H$6
Name Reviewed.by2: [1]Index!$H$7

Sheet Interim Audit Requirements
B1: Client : KHAZAEN ALTAMKEEN For Owner Association Management Services -Project Name - Joya Blanca Residences
B2: Document : Audit Requirement List / Audit Documents Checklist
B3: Audit Period : 01-01-2024 to 30-06-2024
B5: Date: | C5: =TODAY() -> 46246
B6: Place: | C6: Dubai, United Arab Emirates
B8: Accountant/Finance Manager
B9: Client Name: KHAZAEN ALTAMKEEN For Owner Association Management Services -Project Name - Joya Blanca Residences
B10: Dubai, United Arab Emirates
A12: A. | B12: REQUIREMENTS FOR THE AUDIT FOR THE 6 MONTHS PERIOD ENDED 30 JUNE 2024
B14: To commence the interim audit for the above-mentioned period, we would appreciate it if you could provide the following documents at your earliest convenience.
B16: Kindly update the Status column as "Provided" for documents that have been submitted and "Not Applicable" for items that are not applicable to your entity.
B18: Requirement / Document | C18: Evidence / Document Type | D18: STATUS | E18: REMARKS
A19: 1 | B19: SECTION 1: ENTITY DOCUMENTATION & GOVERNANCE
A20: =A19+0.1 -> 1.1 | B20: OA Registration Certificate — current and valid | C20: Original or certified copy of current RERA OA registration certificate | D20: Pending
A21: =A20+0.1 -> 1.2 | B21: OA Constitution / Articles of Association | C21: Filed copy with RERA; any amendments registered to date | D21: Pending
A22: =A21+0.1 -> 1.3 | B22: Board of Directors Resolution — appointment of current Board members | C22: Signed board resolution; RERA notification of current board composition | D22: Pending
A23: =A22+0.1 -> 1.4 | B23: Annual General Meeting (AGM) Minutes — most recent | C23: Signed AGM minutes; attendance register; quorum confirmation | D23: Pending
A24: =A23+0.1 -> 1.5 | B24: Appointment Letter / Contract — Management Company (MC) | C24: Signed MC appointment agreement; RERA-approved MC registration | D24: Pending
A25: =A24+0.1 -> 1.6 | B25: RERA-approved Service Charge Budget for 2026 | C25: RERA-stamped approved budget 2026; RERA approval letter | D25: Pending
A26: =A25+0.1 -> 1.7 | B26: Unit / Common Area Schedule — RERA registered | C26: RERA-registered unit entitlement schedule; DLD strata plan confirmation | D26: Pending
A28: 2 | B28: SERVICE CHARGE ACCOUNTS — GENERAL FUND
A29: =A28+0.1 -> 2.1 | B29: General Fund Trial Balance as at 30 June 2026 | C29: Signed TB; chart of accounts; mapping to approved budget categories | D29: Pending
A30: =A29+0.1 -> 2.2 | B30: Service Charge Levy Schedule — all units, 1 Jan to 30 Jun 2026 | C30: Unit-by-unit levy schedule; calculation basis; RERA unit entitlement percentages | D30: Pending
A31: =A30+0.1 -> 2.3 | B31: Service Charge Collection Register — 1 Jan to 30 Jun 2026 | C31: Full collections listing by unit; amounts billed vs. collected; outstanding balances | D31: Pending
A32: =A31+0.1 -> 2.4 | B32: Arrears Schedule — all units with outstanding service charges as at 30 Jun 2026 | C32: Aged arrears schedule by unit; debt recovery actions taken; legal referrals if any | D32: Pending
A33: =A32+0.1 -> 2.5 | B33: Accounts Receivable Reconciliation — service charge debtors | C33: TB debtors balance vs. collection register; reconciling items explained | D33: Pending
A34: =A33+0.1 -> 2.6 | B34: Refund / Adjustment Register — credits issued to unit owners | C34: Schedule of all refunds and adjustments; authorisation approvals; board resolution if applicable | D34: Pending
A36: 3 | B36: RESERVE FUND — RERA REQUIREMENTS
A37: =A36+0.1 -> 3.1 | B37: Reserve Fund Balance as at 30 June 2026 | C37: Separate reserve fund TB or ledger extract; bank statement confirmation | D37: Pending
A38: =A37+0.1 -> 3.2 | B38: Reserve Fund Contribution Schedule — 1 Jan to 30 Jun 2026 | C38: Unit-by-unit reserve fund levy; total collected; RERA minimum percentage compliance | D38: Pending
A39: =A38+0.1 -> 3.3 | B39: Reserve Fund Study / Long-Term Maintenance Plan — current | C39: Approved reserve fund study (not older than 3 years); specialist certification | D39: Pending
A40: =A39+0.1 -> 3.4 | B40: Reserve Fund Bank Account Statement — 1 Jan to 30 Jun 2026 | C40: Separate segregated reserve fund bank account statements; bank confirmation | D40: Pending
A41: =A40+0.1 -> 3.5 | B41: Reserve Fund Expenditure — approval documentation | C41: Board resolution for each disbursement; invoices; payment receipts | D41: Pending
A43: 4 | B43: BANK ACCOUNTS & CASH MANAGEMENT
A44: =A43+0.1 -> 4.1 | B44: General Fund Bank Account Statements — 1 Jan to 30 Jun 2026 | C44: All bank statements for OA operating accounts; full 6-month period | D44: Pending
A45: =A44+0.1 -> 4.2 | B45: Bank Reconciliation Statements — General Fund, all accounts | C45: Monthly bank reconciliations Jan–Jun 2026; reconciling items cleared | D45: Pending
A46: =A45+0.1 -> 4.3 | B46: Confirmation — Reserve Fund held in separate segregated account | C46: Written bank confirmation that reserve fund is in a separate named account | D46: Pending
A47: =A46+0.1 -> 4.4 | B47: Petty Cash Register and Reconciliation — 1 Jan to 30 Jun 2026 | C47: Petty cash book; receipts; monthly reconciliation; custodian sign-off | D47: Pending
A48: =A47+0.1 -> 4.5 | B48: Fixed Deposit / Investment Account Statements — if applicable | C48: Statements for any term deposits; board resolution authorising investment | D48: Pending
A50: 5 | B50: EXPENDITURE — OPERATING EXPENSES
...

Sheet Audit Status
B2: ='Interim Audit Requirements'!B1 -> Client : KHAZAEN ALTAMKEEN For Owner Association Management Services -Project Name - Joya Blanca Residences
B3: ='Interim Audit Requirements'!B2 -> Document : Audit Requirement List / Audit Documents Checklist
B4: ='Interim Audit Requirements'!B3 -> Audit Period : 01-01-2024 to 30-06-2024
B7: Audit Requirement - Status
B9: Pending | C9: =COUNTIF('Interim Audit Requirements'!D20:D84,"Pending") -> 48
B10: Provided | C10: =COUNTIF('Interim Audit Requirements'!D20:D84,"Provided") -> 0
B11: Not applicable | C11: =COUNTIF('Interim Audit Requirements'!D20:D84,"Not applicable") -> 0
B12: Total | C12: =SUM(C9:C11) -> 48
